+ echo Logging output to experiments/logs/test_res101_voc_2007_trainval_.txt.2018-03-21_16-25-49
Logging output to experiments/logs/test_res101_voc_2007_trainval_.txt.2018-03-21_16-25-49
+ set +x
+ [[ ! -z '' ]]
+ CUDA_VISIBLE_DEVICES=0
+ time python ./tools/test_net.py --imdb voc_2007_test --model output/res101/voc_2007_trainval/default/res101_faster_rcnn_iter_70000.ckpt --cfg experiments/cfgs/res101.yml --net res101 --set ANCHOR_SCALES '[8,16,32]' ANCHOR_RATIOS '[0.5,1,2]'
Called with args:
Namespace(cfg_file='experiments/cfgs/res101.yml', comp_mode=False, imdb_name='voc_2007_test', max_per_image=100, model='output/res101/voc_2007_trainval/default/res101_faster_rcnn_iter_70000.ckpt', net='res101', set_cfgs=['ANCHOR_SCALES', '[8,16,32]', 'ANCHOR_RATIOS', '[0.5,1,2]'], tag='')
Using config:
{'ANCHOR_RATIOS': [0.5, 1, 2],
 'ANCHOR_SCALES': [8, 16, 32],
 'DATA_DIR': '/media/ad/DATA/aicitychallenge/tf-faster-rcnn/data',
 'EXP_DIR': 'res101',
 'MATLAB': 'matlab',
 'MOBILENET': {'DEPTH_MULTIPLIER': 1.0,
               'FIXED_LAYERS': 5,
               'REGU_DEPTH': False,
               'WEIGHT_DECAY': 4e-05},
 'PIXEL_MEANS': array([[[102.9801, 115.9465, 122.7717]]]),
 'POOLING_MODE': 'crop',
 'POOLING_SIZE': 7,
 'RESNET': {'FIXED_BLOCKS': 1, 'MAX_POOL': False},
 'RNG_SEED': 3,
 'ROOT_DIR': '/media/ad/DATA/aicitychallenge/tf-faster-rcnn',
 'RPN_CHANNELS': 512,
 'TEST': {'BBOX_REG': True,
          'HAS_RPN': True,
          'MAX_SIZE': 1000,
          'MODE': 'nms',
          'NMS': 0.3,
          'PROPOSAL_METHOD': 'gt',
          'RPN_NMS_THRESH': 0.7,
          'RPN_POST_NMS_TOP_N': 300,
          'RPN_PRE_NMS_TOP_N': 6000,
          'RPN_TOP_N': 5000,
          'SCALES': [600],
          'SVM': False},
 'TRAIN': {'ASPECT_GROUPING': False,
           'BATCH_SIZE': 256,
           'BBOX_INSIDE_WEIGHTS': [1.0, 1.0, 1.0, 1.0],
           'BBOX_NORMALIZE_MEANS': [0.0, 0.0, 0.0, 0.0],
           'BBOX_NORMALIZE_STDS': [0.1, 0.1, 0.2, 0.2],
           'BBOX_NORMALIZE_TARGETS': True,
           'BBOX_NORMALIZE_TARGETS_PRECOMPUTED': True,
           'BBOX_REG': True,
           'BBOX_THRESH': 0.5,
           'BG_THRESH_HI': 0.5,
           'BG_THRESH_LO': 0.0,
           'BIAS_DECAY': False,
           'DISPLAY': 20,
           'DOUBLE_BIAS': False,
           'FG_FRACTION': 0.25,
           'FG_THRESH': 0.5,
           'GAMMA': 0.1,
           'HAS_RPN': True,
           'IMS_PER_BATCH': 1,
           'LEARNING_RATE': 0.001,
           'MAX_SIZE': 1000,
           'MOMENTUM': 0.9,
           'PROPOSAL_METHOD': 'gt',
           'RPN_BATCHSIZE': 256,
           'RPN_BBOX_INSIDE_WEIGHTS': [1.0, 1.0, 1.0, 1.0],
           'RPN_CLOBBER_POSITIVES': False,
           'RPN_FG_FRACTION': 0.5,
           'RPN_NEGATIVE_OVERLAP': 0.3,
           'RPN_NMS_THRESH': 0.7,
           'RPN_POSITIVE_OVERLAP': 0.7,
           'RPN_POSITIVE_WEIGHT': -1.0,
           'RPN_POST_NMS_TOP_N': 2000,
           'RPN_PRE_NMS_TOP_N': 12000,
           'SCALES': [600],
           'SNAPSHOT_ITERS': 5000,
           'SNAPSHOT_KEPT': 3,
           'SNAPSHOT_PREFIX': 'res101_faster_rcnn',
           'STEPSIZE': [30000],
           'SUMMARY_INTERVAL': 180,
           'TRUNCATED': False,
           'USE_ALL_GT': True,
           'USE_FLIPPED': True,
           'USE_GT': False,
           'WEIGHT_DECAY': 0.0001},
 'USE_GPU_NMS': True}
2018-03-21 16:25:49.973009: I tensorflow/core/platform/cpu_feature_guard.cc:140] Your CPU supports instructions that this TensorFlow binary was not compiled to use: AVX2 FMA
2018-03-21 16:25:50.074233: I tensorflow/stream_executor/cuda/cuda_gpu_executor.cc:898] successful NUMA node read from SysFS had negative value (-1), but there must be at least one NUMA node, so returning NUMA node zero
2018-03-21 16:25:50.074470: I tensorflow/core/common_runtime/gpu/gpu_device.cc:1212] Found device 0 with properties: 
name: GeForce GTX 1080 Ti major: 6 minor: 1 memoryClockRate(GHz): 1.6575
pciBusID: 0000:01:00.0
totalMemory: 10.91GiB freeMemory: 10.40GiB
2018-03-21 16:25:50.074482: I tensorflow/core/common_runtime/gpu/gpu_device.cc:1312] Adding visible gpu devices: 0
2018-03-21 16:25:50.221252: I tensorflow/core/common_runtime/gpu/gpu_device.cc:993] Creating TensorFlow device (/job:localhost/replica:0/task:0/device:GPU:0 with 10063 MB memory) -> physical GPU (device: 0, name: GeForce GTX 1080 Ti, pci bus id: 0000:01:00.0, compute capability: 6.1)
Loading model check point from output/res101/voc_2007_trainval/default/res101_faster_rcnn_iter_70000.ckpt
2018-03-21 16:25:52.474460: W tensorflow/core/framework/op_kernel.cc:1202] OP_REQUIRES failed at save_restore_tensor.cc:170 : Not found: Unsuccessful TensorSliceReader constructor: Failed to find any matching files for output/res101/voc_2007_trainval/default/res101_faster_rcnn_iter_70000.ckpt
Traceback (most recent call last):
  File "./tools/test_net.py", line 113, in <module>
    saver.restore(sess, args.model)
  File "/home/ad/tensorflow-r1.6/local/lib/python2.7/site-packages/tensorflow/python/training/saver.py", line 1755, in restore
    {self.saver_def.filename_tensor_name: save_path})
  File "/home/ad/tensorflow-r1.6/local/lib/python2.7/site-packages/tensorflow/python/client/session.py", line 905, in run
    run_metadata_ptr)
  File "/home/ad/tensorflow-r1.6/local/lib/python2.7/site-packages/tensorflow/python/client/session.py", line 1137, in _run
    feed_dict_tensor, options, run_metadata)
  File "/home/ad/tensorflow-r1.6/local/lib/python2.7/site-packages/tensorflow/python/client/session.py", line 1355, in _do_run
    options, run_metadata)
  File "/home/ad/tensorflow-r1.6/local/lib/python2.7/site-packages/tensorflow/python/client/session.py", line 1374, in _do_call
    raise type(e)(node_def, op, message)
tensorflow.python.framework.errors_impl.NotFoundError: Unsuccessful TensorSliceReader constructor: Failed to find any matching files for output/res101/voc_2007_trainval/default/res101_faster_rcnn_iter_70000.ckpt
	 [[Node: save/RestoreV2 = RestoreV2[dtypes=[DT_FLOAT, DT_FLOAT, DT_FLOAT, DT_FLOAT, DT_FLOAT, ..., DT_FLOAT, DT_FLOAT, DT_FLOAT, DT_FLOAT, DT_FLOAT], _device="/job:localhost/replica:0/task:0/device:CPU:0"](_arg_save/Const_0_0, save/RestoreV2/tensor_names, save/RestoreV2/shape_and_slices)]]
	 [[Node: save/RestoreV2/_301 = _Recv[client_terminated=false, recv_device="/job:localhost/replica:0/task:0/device:GPU:0", send_device="/job:localhost/replica:0/task:0/device:CPU:0", send_device_incarnation=1, tensor_name="edge_306_save/RestoreV2", tensor_type=DT_FLOAT, _device="/job:localhost/replica:0/task:0/device:GPU:0"]()]]

Caused by op u'save/RestoreV2', defined at:
  File "./tools/test_net.py", line 112, in <module>
    saver = tf.train.Saver()
  File "/home/ad/tensorflow-r1.6/local/lib/python2.7/site-packages/tensorflow/python/training/saver.py", line 1293, in __init__
    self.build()
  File "/home/ad/tensorflow-r1.6/local/lib/python2.7/site-packages/tensorflow/python/training/saver.py", line 1302, in build
    self._build(self._filename, build_save=True, build_restore=True)
  File "/home/ad/tensorflow-r1.6/local/lib/python2.7/site-packages/tensorflow/python/training/saver.py", line 1339, in _build
    build_save=build_save, build_restore=build_restore)
  File "/home/ad/tensorflow-r1.6/local/lib/python2.7/site-packages/tensorflow/python/training/saver.py", line 796, in _build_internal
    restore_sequentially, reshape)
  File "/home/ad/tensorflow-r1.6/local/lib/python2.7/site-packages/tensorflow/python/training/saver.py", line 449, in _AddRestoreOps
    restore_sequentially)
  File "/home/ad/tensorflow-r1.6/local/lib/python2.7/site-packages/tensorflow/python/training/saver.py", line 847, in bulk_restore
    return io_ops.restore_v2(filename_tensor, names, slices, dtypes)
  File "/home/ad/tensorflow-r1.6/local/lib/python2.7/site-packages/tensorflow/python/ops/gen_io_ops.py", line 1030, in restore_v2
    shape_and_slices=shape_and_slices, dtypes=dtypes, name=name)
  File "/home/ad/tensorflow-r1.6/local/lib/python2.7/site-packages/tensorflow/python/framework/op_def_library.py", line 787, in _apply_op_helper
    op_def=op_def)
  File "/home/ad/tensorflow-r1.6/local/lib/python2.7/site-packages/tensorflow/python/framework/ops.py", line 3271, in create_op
    op_def=op_def)
  File "/home/ad/tensorflow-r1.6/local/lib/python2.7/site-packages/tensorflow/python/framework/ops.py", line 1650, in __init__
    self._traceback = self._graph._extract_stack()  # pylint: disable=protected-access

NotFoundError (see above for traceback): Unsuccessful TensorSliceReader constructor: Failed to find any matching files for output/res101/voc_2007_trainval/default/res101_faster_rcnn_iter_70000.ckpt
	 [[Node: save/RestoreV2 = RestoreV2[dtypes=[DT_FLOAT, DT_FLOAT, DT_FLOAT, DT_FLOAT, DT_FLOAT, ..., DT_FLOAT, DT_FLOAT, DT_FLOAT, DT_FLOAT, DT_FLOAT], _device="/job:localhost/replica:0/task:0/device:CPU:0"](_arg_save/Const_0_0, save/RestoreV2/tensor_names, save/RestoreV2/shape_and_slices)]]
	 [[Node: save/RestoreV2/_301 = _Recv[client_terminated=false, recv_device="/job:localhost/replica:0/task:0/device:GPU:0", send_device="/job:localhost/replica:0/task:0/device:CPU:0", send_device_incarnation=1, tensor_name="edge_306_save/RestoreV2", tensor_type=DT_FLOAT, _device="/job:localhost/replica:0/task:0/device:GPU:0"]()]]

Command exited with non-zero status 1
3.38user 0.90system 0:03.60elapsed 118%CPU (0avgtext+0avgdata 858596maxresident)k
352inputs+0outputs (0major+168074minor)pagefaults 0swaps
